Workbook

Sheet Instrucciones
B2: Finanzas GM Growth Partners
B3: Entradas, salidas, impuestos mes a mes y retiros — en un solo archivo.
B5: Cómo funciona
B6: Escribes en tres hojas — Ingresos, Gastos y Retiros — y todo lo demás se calcula solo. No hay que tocar ninguna fórmula.
B9: Los colores te dicen qué tocar
B10: Azul sobre fondo amarillo | C10: lo escribes tú
B11: Negro | C11: fórmula de la misma hoja — no la toques
B12: Verde | C12: trae un dato de otra hoja — no la toques
B14: Las 8 hojas
B15: Hoja | C15: Para qué sirve | D15: Qué haces ahí
B16: Resumen | C16: El año de un vistazo: seis números, la tabla mes a mes y dos gráficos. | D16: Sólo mirar
B17: Ingresos | C17: Cada factura o boleta que emites. | D17: ESCRIBES ACÁ
B18: Gastos | C18: Cada documento que recibes y pagas. | D18: ESCRIBES ACÁ
B19: Retiros | C19: Cada giro de utilidades a tu cuenta personal, y qué impuesto te va a costar. | D19: ESCRIBES ACÁ
B20: Mensual | C20: Tu F29 mes a mes: IVA, PPM y retenciones. | D20: Sólo mirar
B21: Renta | C21: El impuesto anual de la empresa y qué utilidad queda. | D21: Sólo mirar
B22: Flujo | C22: Caja mes a mes: con qué cuentas de verdad. | D22: Sólo mirar
B23: Parámetros | C23: Tasas, UTM, listas y saldos iniciales. | D23: Ajustas 1 vez al año
B26: Cada mes, en 10 minutos
B27: 1. | C27: Carga en Ingresos las facturas que emitiste, con su fecha de emisión.
B28: 2. | C28: Cuando un cliente te paga, vuelve a esa fila y llena «Fecha de pago» y cambia el estado a Pagada.
B29: 3. | C29: Carga en Gastos todo documento recibido: escribe el monto tal como viene y marca si trae IVA adentro.
B30: 4. | C30: Anota en Retiros lo que sacaste a tu cuenta personal.
B31: 5. | C31: Abre Mensual, busca el mes y mira la columna «TOTAL F29 del mes»: eso declaras y pagas hasta el día 20.
B32: 6. | C32: Mira Flujo: si algún mes que viene queda en rojo, ya lo sabes con anticipación.
B35: Una vez al año
B36: 1. | C36: En enero: actualiza las tasas de Parámetros §2 (cambian casi todos los años) y los valores de UTM.
B37: 2. | C37: En enero: copia el saldo final de caja de diciembre al «Caja + banco al 1 de enero» del archivo nuevo, y el remanente de crédito fiscal si quedó.
B38: 3. | C38: En marzo-abril: la hoja Renta te dice cuánto sale la Operación Renta de la empresa.
B39: 4. | C39: En marzo-abril: la hoja Retiros te dice cuánto te va a cobrar a TI el Global Complementario por lo que retiraste.
B40: 5. | C40: Para llevar otro año: duplica el archivo completo y cambia el «Año de trabajo» en Parámetros.
B43: Cuatro cosas que conviene tener claras
B44: Base caja, no devengado
B45: El régimen Pro Pyme paga impuesto sobre lo que COBRASTE, no sobre lo que facturaste. Por eso cada ingreso lleva dos fechas: la de emisión (manda para el IVA) y la de pago (manda para la renta y el flujo). Llenar sólo una deja la mitad del libro en cero.
B48: El IVA no es tuyo
B49: El 19% que le cobras al cliente es plata del SII que pasa por tu cuenta. Si la miras como ingreso, en el F29 te va a faltar. El «Resultado» del Resumen ya viene neto de IVA, a propósito.
B52: Un retiro no es un gasto
B53: Sacar plata a tu cuenta personal no baja el impuesto de la empresa: es utilidad repartida y encima paga tu Global Complementario. Por eso los retiros tienen hoja propia y no aparecen en Gastos.
B56: Esto ordena, no reemplaza al contador
B57: Es una herramienta de gestión para que sepas dónde estás parado cualquier día del mes. La declaración oficial —con corrección monetaria, depreciación y arrastre de pérdidas— la firma tu contador.
...

Sheet Resumen
A1: Resumen del año
A2: =Parámetros!$B$7&" · año "&Parámetros!$B$10
A5: INGRESOS COBRADOS | E5: GASTOS PAGADOS | I5: UTILIDAD ANTES DE IMPUESTO
A6: =Renta!$C$7 | E6: =-Renta!$C$8 | I6: =Renta!$C$9
A7: Facturado y percibido en el año | E7: Sólo lo aceptado por el SII | I7: Ingresos menos gastos
A10: IMPUESTO A LA RENTA | E10: RETIRADO A TU CUENTA | I10: CAJA AL 31 DE DICIEMBRE
A11: =Renta!$C$12 | E11: =SUMIFS(Retiros!$B$8:$B$67,Retiros!$E$8:$E$67,Parámetros!$B$10) | I11: =Flujo!$H$19
A12: 1ª Categoría del año | E12: Giros de utilidades | I12: Saldo proyectado de banco
A13: =IFERROR(Renta!$C$9/Renta!$C$7,0) | B13: margen neto sobre lo cobrado
A14: Mes | B14: Ingresos | C14: Gastos | D14: Resultado | E14: Impuestos (F29) | F14: Retiros | G14: Caja al cierre
A15: Enero | B15: =Mensual!$K$8 | C15: =SUMIFS(Gastos!$M$8:$M$257,Gastos!$U$8:$U$257,Parámetros!$B$10,Gastos!$V$8:$V$257,1)-SUMIFS(Gastos!$K$8:$K$257,Gastos!$U$8:$U$257,Parámetros!$B$10,Gastos!$V$8:$V$257,1) | D15: =$B15-$C15 | E15: =Mensual!$N$8 | F15: =-Flujo!$G$8 | G15: =Flujo!$H$8
A16: Febrero | B16: =Mensual!$K$9 | C16: =SUMIFS(Gastos!$M$8:$M$257,Gastos!$U$8:$U$257,Parámetros!$B$10,Gastos!$V$8:$V$257,2)-SUMIFS(Gastos!$K$8:$K$257,Gastos!$U$8:$U$257,Parámetros!$B$10,Gastos!$V$8:$V$257,2) | D16: =$B16-$C16 | E16: =Mensual!$N$9 | F16: =-Flujo!$G$9 | G16: =Flujo!$H$9
A17: Marzo | B17: =Mensual!$K$10 | C17: =SUMIFS(Gastos!$M$8:$M$257,Gastos!$U$8:$U$257,Parámetros!$B$10,Gastos!$V$8:$V$257,3)-SUMIFS(Gastos!$K$8:$K$257,Gastos!$U$8:$U$257,Parámetros!$B$10,Gastos!$V$8:$V$257,3) | D17: =$B17-$C17 | E17: =Mensual!$N$10 | F17: =-Flujo!$G$10 | G17: =Flujo!$H$10
A18: Abril | B18: =Mensual!$K$11 | C18: =SUMIFS(Gastos!$M$8:$M$257,Gastos!$U$8:$U$257,Parámetros!$B$10,Gastos!$V$8:$V$257,4)-SUMIFS(Gastos!$K$8:$K$257,Gastos!$U$8:$U$257,Parámetros!$B$10,Gastos!$V$8:$V$257,4) | D18: =$B18-$C18 | E18: =Mensual!$N$11 | F18: =-Flujo!$G$11 | G18: =Flujo!$H$11
A19: Mayo | B19: =Mensual!$K$12 | C19: =SUMIFS(Gastos!$M$8:$M$257,Gastos!$U$8:$U$257,Parámetros!$B$10,Gastos!$V$8:$V$257,5)-SUMIFS(Gastos!$K$8:$K$257,Gastos!$U$8:$U$257,Parámetros!$B$10,Gastos!$V$8:$V$257,5) | D19: =$B19-$C19 | E19: =Mensual!$N$12 | F19: =-Flujo!$G$12 | G19: =Flujo!$H$12
A20: Junio | B20: =Mensual!$K$13 | C20: =SUMIFS(Gastos!$M$8:$M$257,Gastos!$U$8:$U$257,Parámetros!$B$10,Gastos!$V$8:$V$257,6)-SUMIFS(Gastos!$K$8:$K$257,Gastos!$U$8:$U$257,Parámetros!$B$10,Gastos!$V$8:$V$257,6) | D20: =$B20-$C20 | E20: =Mensual!$N$13 | F20: =-Flujo!$G$13 | G20: =Flujo!$H$13
A21: Julio | B21: =Mensual!$K$14 | C21: =SUMIFS(Gastos!$M$8:$M$257,Gastos!$U$8:$U$257,Parámetros!$B$10,Gastos!$V$8:$V$257,7)-SUMIFS(Gastos!$K$8:$K$257,Gastos!$U$8:$U$257,Parámetros!$B$10,Gastos!$V$8:$V$257,7) | D21: =$B21-$C21 | E21: =Mensual!$N$14 | F21: =-Flujo!$G$14 | G21: =Flujo!$H$14
A22: Agosto | B22: =Mensual!$K$15 | C22: =SUMIFS(Gastos!$M$8:$M$257,Gastos!$U$8:$U$257,Parámetros!$B$10,Gastos!$V$8:$V$257,8)-SUMIFS(Gastos!$K$8:$K$257,Gastos!$U$8:$U$257,Parámetros!$B$10,Gastos!$V$8:$V$257,8) | D22: =$B22-$C22 | E22: =Mensual!$N$15 | F22: =-Flujo!$G$15 | G22: =Flujo!$H$15
A23: Septiembre | B23: =Mensual!$K$16 | C23: =SUMIFS(Gastos!$M$8:$M$257,Gastos!$U$8:$U$257,Parámetros!$B$10,Gastos!$V$8:$V$257,9)-SUMIFS(Gastos!$K$8:$K$257,Gastos!$U$8:$U$257,Parámetros!$B$10,Gastos!$V$8:$V$257,9) | D23: =$B23-$C23 | E23: =Mensual!$N$16 | F23: =-Flujo!$G$16 | G23: =Flujo!$H$16
A24: Octubre | B24: =Mensual!$K$17 | C24: =SUMIFS(Gastos!$M$8:$M$257,Gastos!$U$8:$U$257,Parámetros!$B$10,Gastos!$V$8:$V$257,10)-SUMIFS(Gastos!$K$8:$K$257,Gastos!$U$8:$U$257,Parámetros!$B$10,Gastos!$V$8:$V$257,10) | D24: =$B24-$C24 | E24: =Mensual!$N$17 | F24: =-Flujo!$G$17 | G24: =Flujo!$H$17
A25: Noviembre | B25: =Mensual!$K$18 | C25: =SUMIFS(Gastos!$M$8:$M$257,Gastos!$U$8:$U$257,Parámetros!$B$10,Gastos!$V$8:$V$257,11)-SUMIFS(Gastos!$K$8:$K$257,Gastos!$U$8:$U$257,Parámetros!$B$10,Gastos!$V$8:$V$257,11) | D25: =$B25-$C25 | E25: =Mensual!$N$18 | F25: =-Flujo!$G$18 | G25: =Flujo!$H$18
A26: Diciembre | B26: =Mensual!$K$19 | C26: =SUMIFS(Gastos!$M$8:$M$257,Gastos!$U$8:$U$257,Parámetros!$B$10,Gastos!$V$8:$V$257,12)-SUMIFS(Gastos!$K$8:$K$257,Gastos!$U$8:$U$257,Parámetros!$B$10,Gastos!$V$8:$V$257,12) | D26: =$B26-$C26 | E26: =Mensual!$N$19 | F26: =-Flujo!$G$19 | G26: =Flujo!$H$19
A27: TOTAL | B27: =SUM(B15:B26) | C27: =SUM(C15:C26) | D27: =SUM(D15:D26) | E27: =SUM(E15:E26) | F27: =SUM(F15:F26) | G27: =G26
A29: Ingresos y gastos van por fecha de PAGO: es la plata que se movió, no la que facturaste. «Resultado» es utilidad de gestión, antes de impuesto a la renta.
A31: Si el resultado es bueno y la caja igual va cayendo, la respuesta casi siempre está en los retiros o en clientes que pagan tarde.

Sheet Ingresos
A1: Ingresos
A2: Una fila por documento que EMITES. El IVA se declara con la fecha de emisión; la plata entra con la fecha de pago — por eso van dos fechas.
A4: Azul = lo escribes tú | D4: Negro = fórmula, no tocar | G4: Verde = viene de otra hoja
A5: Las 3 primeras filas son un ejemplo del formato esperado: bórralas cuando empieces a cargar lo tuyo. Para anular o rebajar una factura ya emitida, agrega una fila con tipo «Nota de crédito emitida» y el monto en NEGATIVO.
A7: Fecha emisión | B7: N° documento | C7: Tipo de documento | D7: Cliente | E7: Descripción / proyecto | F7: Neto ($) | G7: IVA ($) | H7: Total ($) | I7: Estado | J7: Fecha de pago | K7: Medio de pago | L7: Año emis. | M7: Mes emis. | N7: Año pago | O7: Mes pago
A8: 46027 | B8: F-001 | C8: Factura afecta | D8: Bike Trust SpA | E8: Retainer enero · growth + automatización | F8: 1200000 | G8: =IF($F8="","",IF(IFERROR(INDEX(Parámetros!$B$64:$B$68,MATCH($C8,Parámetros!$A$64:$A$68,0)),0)=1,ROUND($F8*Parámetros!$B$13,0),0)) | H8: =IF($F8="","",$F8+$G8) | I8: Pagada | J8: 46050 | K8: Transferencia | L8: =IF($A8="","",YEAR($A8)) | M8: =IF($A8="","",MONTH($A8)) | N8: =IF($J8="","",YEAR($J8)) | O8: =IF($J8="","",MONTH($J8))
A9: 46042 | B9: F-002 | C9: Factura afecta | D9: Cliente Demo Ltda. | E9: Proyecto sitio web · hito 1 | F9: 850000 | G9: =IF($F9="","",IF(IFERROR(INDEX(Parámetros!$B$64:$B$68,MATCH($C9,Parámetros!$A$64:$A$68,0)),0)=1,ROUND($F9*Parámetros!$B$13,0),0)) | H9: =IF($F9="","",$F9+$G9) | I9: Pagada | J9: 46063 | K9: Transferencia | L9: =IF($A9="","",YEAR($A9)) | M9: =IF($A9="","",MONTH($A9)) | N9: =IF($J9="","",YEAR($J9)) | O9: =IF($J9="","",MONTH($J9))
A10: 46056 | B10: F-003 | C10: Factura de exportación | D10: Acme Inc. (EE.UU.) | E10: Consultoría growth · 2 semanas | F10: 1500000 | G10: =IF($F10="","",IF(IFERROR(INDEX(Parámetros!$B$64:$B$68,MATCH($C10,Parámetros!$A$64:$A$68,0)),0)=1,ROUND($F10*Parámetros!$B$13,0),0)) | H10: =IF($F10="","",$F10+$G10) | I10: Pendiente de pago | L10: =IF($A10="","",YEAR($A10)) | M10: =IF($A10="","",MONTH($A10)) | N10: =IF($J10="","",YEAR($J10)) | O10: =IF($J10="","",MONTH($J10))
G11: =IF($F11="","",IF(IFERROR(INDEX(Parámetros!$B$64:$B$68,MATCH($C11,Parámetros!$A$64:$A$68,0)),0)=1,ROUND($F11*Parámetros!$B$13,0),0)) | H11: =IF($F11="","",$F11+$G11) | L11: =IF($A11="","",YEAR($A11)) | M11: =IF($A11="","",MONTH($A11)) | N11: =IF($J11="","",YEAR($J11)) | O11: =IF($J11="","",MONTH($J11))
G12: =IF($F12="","",IF(IFERROR(INDEX(Parámetros!$B$64:$B$68,MATCH($C12,Parámetros!$A$64:$A$68,0)),0)=1,ROUND($F12*Parámetros!$B$13,0),0)) | H12: =IF($F12="","",$F12+$G12) | L12: =IF($A12="","",YEAR($A12)) | M12: =IF($A12="","",MONTH($A12)) | N12: =IF($J12="","",YEAR($J12)) | O12: =IF($J12="","",MONTH($J12))
G13: =IF($F13="","",IF(IFERROR(INDEX(Parámetros!$B$64:$B$68,MATCH($C13,Parámetros!$A$64:$A$68,0)),0)=1,ROUND($F13*Parámetros!$B$13,0),0)) | H13: =IF($F13="","",$F13+$G13) | L13: =IF($A13="","",YEAR($A13)) | M13: =IF($A13="","",MONTH($A13)) | N13: =IF($J13="","",YEAR($J13)) | O13: =IF($J13="","",MONTH($J13))
G14: =IF($F14="","",IF(IFERROR(INDEX(Parámetros!$B$64:$B$68,MATCH($C14,Parámetros!$A$64:$A$68,0)),0)=1,ROUND($F14*Parámetros!$B$13,0),0)) | H14: =IF($F14="","",$F14+$G14) | L14: =IF($A14="","",YEAR($A14)) | M14: =IF($A14="","",MONTH($A14)) | N14: =IF($J14="","",YEAR($J14)) | O14: =IF($J14="","",MONTH($J14))
G15: =IF($F15="","",IF(IFERROR(INDEX(Parámetros!$B$64:$B$68,MATCH($C15,Parámetros!$A$64:$A$68,0)),0)=1,ROUND($F15*Parámetros!$B$13,0),0)) | H15: =IF($F15="","",$F15+$G15) | L15: =IF($A15="","",YEAR($A15)) | M15: =IF($A15="","",MONTH($A15)) | N15: =IF($J15="","",YEAR($J15)) | O15: =IF($J15="","",MONTH($J15))
G16: =IF($F16="","",IF(IFERROR(INDEX(Parámetros!$B$64:$B$68,MATCH($C16,Parámetros!$A$64:$A$68,0)),0)=1,ROUND($F16*Parámetros!$B$13,0),0)) | H16: =IF($F16="","",$F16+$G16) | L16: =IF($A16="","",YEAR($A16)) | M16: =IF($A16="","",MONTH($A16)) | N16: =IF($J16="","",YEAR($J16)) | O16: =IF($J16="","",MONTH($J16))
G17: =IF($F17="","",IF(IFERROR(INDEX(Parámetros!$B$64:$B$68,MATCH($C17,Parámetros!$A$64:$A$68,0)),0)=1,ROUND($F17*Parámetros!$B$13,0),0)) | H17: =IF($F17="","",$F17+$G17) | L17: =IF($A17="","",YEAR($A17)) | M17: =IF($A17="","",MONTH($A17)) | N17: =IF($J17="","",YEAR($J17)) | O17: =IF($J17="","",MONTH($J17))
G18: =IF($F18="","",IF(IFERROR(INDEX(Parámetros!$B$64:$B$68,MATCH($C18,Parámetros!$A$64:$A$68,0)),0)=1,ROUND($F18*Parámetros!$B$13,0),0)) | H18: =IF($F18="","",$F18+$G18) | L18: =IF($A18="","",YEAR($A18)) | M18: =IF($A18="","",MONTH($A18)) | N18: =IF($J18="","",YEAR($J18)) | O18: =IF($J18="","",MONTH($J18))
G19: =IF($F19="","",IF(IFERROR(INDEX(Parámetros!$B$64:$B$68,MATCH($C19,Parámetros!$A$64:$A$68,0)),0)=1,ROUND($F19*Parámetros!$B$13,0),0)) | H19: =IF($F19="","",$F19+$G19) | L19: =IF($A19="","",YEAR($A19)) | M19: =IF($A19="","",MONTH($A19)) | N19: =IF($J19="","",YEAR($J19)) | O19: =IF($J19="","",MONTH($J19))
G20: =IF($F20="","",IF(IFERROR(INDEX(Parámetros!$B$64:$B$68,MATCH($C20,Parámetros!$A$64:$A$68,0)),0)=1,ROUND($F20*Parámetros!$B$13,0),0)) | H20: =IF($F20="","",$F20+$G20) | L20: =IF($A20="","",YEAR($A20)) | M20: =IF($A20="","",MONTH($A20)) | N20: =IF($J20="","",YEAR($J20)) | O20: =IF($J20="","",MONTH($J20))
G21: =IF($F21="","",IF(IFERROR(INDEX(Parámetros!$B$64:$B$68,MATCH($C21,Parámetros!$A$64:$A$68,0)),0)=1,ROUND($F21*Parámetros!$B$13,0),0)) | H21: =IF($F21="","",$F21+$G21) | L21: =IF($A21="","",YEAR($A21)) | M21: =IF($A21="","",MONTH($A21)) | N21: =IF($J21="","",YEAR($J21)) | O21: =IF($J21="","",MONTH($J21))
G22: =IF($F22="","",IF(IFERROR(INDEX(Parámetros!$B$64:$B$68,MATCH($C22,Parámetros!$A$64:$A$68,0)),0)=1,ROUND($F22*Parámetros!$B$13,0),0)) | H22: =IF($F22="","",$F22+$G22) | L22: =IF($A22="","",YEAR($A22)) | M22: =IF($A22="","",MONTH($A22)) | N22: =IF($J22="","",YEAR($J22)) | O22: =IF($J22="","",MONTH($J22))
... G157: =IF($F157="","",IF(IFERROR(INDEX(Parámetros!$B$64:$B$68,MATCH($C157,Parámetros!$A$64:$A$68,0)),0)=1,ROUND($F157*Parámetros!$B$13,0),0)) | H157: =IF($F157="","",$F157+$G157) | L157: =IF($A157="","",YEAR($A157)) | M157: =IF($A157="","",MONTH($A157)) | N157: =IF($J157="","",YEAR($J157)) | O157: =IF($J157="","",MONTH($J157))

Sheet Gastos
A1: Gastos
A2: Una fila por documento que RECIBES. Escribe el monto tal como viene en el documento y marca si trae IVA adentro: el resto se calcula solo.
A4: Azul = lo escribes tú | D4: Negro = fórmula, no tocar | G4: Verde = viene de otra hoja
A5: Las 3 primeras filas son un ejemplo del formato esperado: bórralas cuando empieces. «¿Gasto aceptado?» = si el SII lo acepta como gasto de la empresa. Todo lo personal va en No (y en rigor no debería pasar por la cuenta de la empresa).
A7: Fecha doc. | B7: N° documento | C7: Tipo de documento | D7: Proveedor | E7: Categoría | F7: Descripción | G7: Monto del doc. ($) | H7: ¿Incluye IVA? | I7: Neto ($) | J7: IVA ($) | K7: Crédito fiscal ($) | L7: Retención ($) | M7: Total doc. ($) | N7: Pago al proveedor ($) | O7: ¿Gasto aceptado? | P7: Estado | Q7: Fecha de pago | R7: Medio de pago | S7: Año doc. | T7: Mes doc. | U7: Año pago | V7: Mes pago
A8: 46024 | B8: F-88213 | C8: Factura afecta | D8: Contador Pérez y Cía. | E8: Contabilidad y legal | F8: Honorarios contables enero | G8: 150000 | H8: No | I8: =IF($G8="","",IF(AND($H8="Sí",IFERROR(INDEX(Parámetros!$B$54:$B$60,MATCH($C8,Parámetros!$A$54:$A$60,0)),0)=1),ROUND($G8/(1+Parámetros!$B$13),0),$G8)) | J8: =IF($G8="","",IF(IFERROR(INDEX(Parámetros!$B$54:$B$60,MATCH($C8,Parámetros!$A$54:$A$60,0)),0)=1,ROUND($I8*Parámetros!$B$13,0),0)) | K8: =IF($G8="","",IF(IFERROR(INDEX(Parámetros!$C$54:$C$60,MATCH($C8,Parámetros!$A$54:$A$60,0)),0)=1,$J8,0)) | L8: =IF($G8="","",IF(IFERROR(INDEX(Parámetros!$D$54:$D$60,MATCH($C8,Parámetros!$A$54:$A$60,0)),0)=1,ROUND($I8*Parámetros!$B$16,0),0)) | M8: =IF($G8="","",$I8+$J8) | N8: =IF($G8="","",$M8-$L8) | O8: Sí | P8: Pagado | Q8: 46027 | R8: Transferencia | S8: =IF($A8="","",YEAR($A8)) | T8: =IF($A8="","",MONTH($A8)) | U8: =IF($Q8="","",YEAR($Q8)) | V8: =IF($Q8="","",MONTH($Q8))
A9: 46030 | B9: — | C9: Servicio digital extranjero | D9: Anthropic | E9: Software y suscripciones | F9: Claude · plan equipo | G9: 71400 | H9: Sí | I9: =IF($G9="","",IF(AND($H9="Sí",IFERROR(INDEX(Parámetros!$B$54:$B$60,MATCH($C9,Parámetros!$A$54:$A$60,0)),0)=1),ROUND($G9/(1+Parámetros!$B$13),0),$G9)) | J9: =IF($G9="","",IF(IFERROR(INDEX(Parámetros!$B$54:$B$60,MATCH($C9,Parámetros!$A$54:$A$60,0)),0)=1,ROUND($I9*Parámetros!$B$13,0),0)) | K9: =IF($G9="","",IF(IFERROR(INDEX(Parámetros!$C$54:$C$60,MATCH($C9,Parámetros!$A$54:$A$60,0)),0)=1,$J9,0)) | L9: =IF($G9="","",IF(IFERROR(INDEX(Parámetros!$D$54:$D$60,MATCH($C9,Parámetros!$A$54:$A$60,0)),0)=1,ROUND($I9*Parámetros!$B$16,0),0)) | M9: =IF($G9="","",$I9+$J9) | N9: =IF($G9="","",$M9-$L9) | O9: Sí | P9: Pagado | Q9: 46030 | R9: Tarjeta de crédito | S9: =IF($A9="","",YEAR($A9)) | T9: =IF($A9="","",MONTH($A9)) | U9: =IF($Q9="","",YEAR($Q9)) | V9: =IF($Q9="","",MONTH($Q9))
A10: 46037 | B10: BH-412 | C10: Boleta de honorarios recibida | D10: Diseñador freelance | E10: Subcontratos y freelance | F10: Diseño de fichas · proyecto Bike Trust | G10: 400000 | H10: No | I10: =IF($G10="","",IF(AND($H10="Sí",IFERROR(INDEX(Parámetros!$B$54:$B$60,MATCH($C10,Parámetros!$A$54:$A$60,0)),0)=1),ROUND($G10/(1+Parámetros!$B$13),0),$G10)) | J10: =IF($G10="","",IF(IFERROR(INDEX(Parámetros!$B$54:$B$60,MATCH($C10,Parámetros!$A$54:$A$60,0)),0)=1,ROUND($I10*Parámetros!$B$13,0),0)) | K10: =IF($G10="","",IF(IFERROR(INDEX(Parámetros!$C$54:$C$60,MATCH($C10,Parámetros!$A$54:$A$60,0)),0)=1,$J10,0)) | L10: =IF($G10="","",IF(IFERROR(INDEX(Parámetros!$D$54:$D$60,MATCH($C10,Parámetros!$A$54:$A$60,0)),0)=1,ROUND($I10*Parámetros!$B$16,0),0)) | M10: =IF($G10="","",$I10+$J10) | N10: =IF($G10="","",$M10-$L10) | O10: Sí | P10: Pagado | Q10: 46042 | R10: Transferencia | S10: =IF($A10="","",YEAR($A10)) | T10: =IF($A10="","",MONTH($A10)) | U10: =IF($Q10="","",YEAR($Q10)) | V10: =IF($Q10="","",MONTH($Q10))
I11: =IF($G11="","",IF(AND($H11="Sí",IFERROR(INDEX(Parámetros!$B$54:$B$60,MATCH($C11,Parámetros!$A$54:$A$60,0)),0)=1),ROUND($G11/(1+Parámetros!$B$13),0),$G11)) | J11: =IF($G11="","",IF(IFERROR(INDEX(Parámetros!$B$54:$B$60,MATCH($C11,Parámetros!$A$54:$A$60,0)),0)=1,ROUND($I11*Parámetros!$B$13,0),0)) | K11: =IF($G11="","",IF(IFERROR(INDEX(Parámetros!$C$54:$C$60,MATCH($C11,Parámetros!$A$54:$A$60,0)),0)=1,$J11,0)) | L11: =IF($G11="","",IF(IFERROR(INDEX(Parámetros!$D$54:$D$60,MATCH($C11,Parámetros!$A$54:$A$60,0)),0)=1,ROUND($I11*Parámetros!$B$16,0),0)) | M11: =IF($G11="","",$I11+$J11) | N11: =IF($G11="","",$M11-$L11) | S11: =IF($A11="","",YEAR($A11)) | T11: =IF($A11="","",MONTH($A11)) | U11: =IF($Q11="","",YEAR($Q11)) | V11: =IF($Q11="","",MONTH($Q11))
I12: =IF($G12="","",IF(AND($H12="Sí",IFERROR(INDEX(Parámetros!$B$54:$B$60,MATCH($C12,Parámetros!$A$54:$A$60,0)),0)=1),ROUND($G12/(1+Parámetros!$B$13),0),$G12)) | J12: =IF($G12="","",IF(IFERROR(INDEX(Parámetros!$B$54:$B$60,MATCH($C12,Parámetros!$A$54:$A$60,0)),0)=1,ROUND($I12*Parámetros!$B$13,0),0)) | K12: =IF($G12="","",IF(IFERROR(INDEX(Parámetros!$C$54:$C$60,MATCH($C12,Parámetros!$A$54:$A$60,0)),0)=1,$J12,0)) | L12: =IF($G12="","",IF(IFERROR(INDEX(Parámetros!$D$54:$D$60,MATCH($C12,Parámetros!$A$54:$A$60,0)),0)=1,ROUND($I12*Parámetros!$B$16,0),0)) | M12: =IF($G12="","",$I12+$J12) | N12: =IF($G12="","",$M12-$L12) | S12: =IF($A12="","",YEAR($A12)) | T12: =IF($A12="","",MONTH($A12)) | U12: =IF($Q12="","",YEAR($Q12)) | V12: =IF($Q12="","",MONTH($Q12))
I13: =IF($G13="","",IF(AND($H13="Sí",IFERROR(INDEX(Parámetros!$B$54:$B$60,MATCH($C13,Parámetros!$A$54:$A$60,0)),0)=1),ROUND($G13/(1+Parámetros!$B$13),0),$G13)) | J13: =IF($G13="","",IF(IFERROR(INDEX(Parámetros!$B$54:$B$60,MATCH($C13,Parámetros!$A$54:$A$60,0)),0)=1,ROUND($I13*Parámetros!$B$13,0),0)) | K13: =IF($G13="","",IF(IFERROR(INDEX(Parámetros!$C$54:$C$60,MATCH($C13,Parámetros!$A$54:$A$60,0)),0)=1,$J13,0)) | L13: =IF($G13="","",IF(IFERROR(INDEX(Parámetros!$D$54:$D$60,MATCH($C13,Parámetros!$A$54:$A$60,0)),0)=1,ROUND($I13*Parámetros!$B$16,0),0)) | M13: =IF($G13="","",$I13+$J13) | N13: =IF($G13="","",$M13-$L13) | S13: =IF($A13="","",YEAR($A13)) | T13: =IF($A13="","",MONTH($A13)) | U13: =IF($Q13="","",YEAR($Q13)) | V13: =IF($Q13="","",MONTH($Q13))
I14: =IF($G14="","",IF(AND($H14="Sí",IFERROR(INDEX(Parámetros!$B$54:$B$60,MATCH($C14,Parámetros!$A$54:$A$60,0)),0)=1),ROUND($G14/(1+Parámetros!$B$13),0),$G14)) | J14: =IF($G14="","",IF(IFERROR(INDEX(Parámetros!$B$54:$B$60,MATCH($C14,Parámetros!$A$54:$A$60,0)),0)=1,ROUND($I14*Parámetros!$B$13,0),0)) | K14: =IF($G14="","",IF(IFERROR(INDEX(Parámetros!$C$54:$C$60,MATCH($C14,Parámetros!$A$54:$A$60,0)),0)=1,$J14,0)) | L14: =IF($G14="","",IF(IFERROR(INDEX(Parámetros!$D$54:$D$60,MATCH($C14,Parámetros!$A$54:$A$60,0)),0)=1,ROUND($I14*Parámetros!$B$16,0),0)) | M14: =IF($G14="","",$I14+$J14) | N14: =IF($G14="","",$M14-$L14) | S14: =IF($A14="","",YEAR($A14)) | T14: =IF($A14="","",MONTH($A14)) | U14: =IF($Q14="","",YEAR($Q14)) | V14: =IF($Q14="","",MONTH($Q14))
I15: =IF($G15="","",IF(AND($H15="Sí",IFERROR(INDEX(Parámetros!$B$54:$B$60,MATCH($C15,Parámetros!$A$54:$A$60,0)),0)=1),ROUND($G15/(1+Parámetros!$B$13),0),$G15)) | J15: =IF($G15="","",IF(IFERROR(INDEX(Parámetros!$B$54:$B$60,MATCH($C15,Parámetros!$A$54:$A$60,0)),0)=1,ROUND($I15*Parámetros!$B$13,0),0)) | K15: =IF($G15="","",IF(IFERROR(INDEX(Parámetros!$C$54:$C$60,MATCH($C15,Parámetros!$A$54:$A$60,0)),0)=1,$J15,0)) | L15: =IF($G15="","",IF(IFERROR(INDEX(Parámetros!$D$54:$D$60,MATCH($C15,Parámetros!$A$54:$A$60,0)),0)=1,ROUND($I15*Parámetros!$B$16,0),0)) | M15: =IF($G15="","",$I15+$J15) | N15: =IF($G15="","",$M15-$L15) | S15: =IF($A15="","",YEAR($A15)) | T15: =IF($A15="","",MONTH($A15)) | U15: =IF($Q15="","",YEAR($Q15)) | V15: =IF($Q15="","",MONTH($Q15))
I16: =IF($G16="","",IF(AND($H16="Sí",IFERROR(INDEX(Parámetros!$B$54:$B$60,MATCH($C16,Parámetros!$A$54:$A$60,0)),0)=1),ROUND($G16/(1+Parámetros!$B$13),0),$G16)) | J16: =IF($G16="","",IF(IFERROR(INDEX(Parámetros!$B$54:$B$60,MATCH($C16,Parámetros!$A$54:$A$60,0)),0)=1,ROUND($I16*Parámetros!$B$13,0),0)) | K16: =IF($G16="","",IF(IFERROR(INDEX(Parámetros!$C$54:$C$60,MATCH($C16,Parámetros!$A$54:$A$60,0)),0)=1,$J16,0)) | L16: =IF($G16="","",IF(IFERROR(INDEX(Parámetros!$D$54:$D$60,MATCH($C16,Parámetros!$A$54:$A$60,0)),0)=1,ROUND($I16*Parámetros!$B$16,0),0)) | M16: =IF($G16="","",$I16+$J16) | N16: =IF($G16="","",$M16-$L16) | S16: =IF($A16="","",YEAR($A16)) | T16: =IF($A16="","",MONTH($A16)) | U16: =IF($Q16="","",YEAR($Q16)) | V16: =IF($Q16="","",MONTH($Q16))
I17: =IF($G17="","",IF(AND($H17="Sí",IFERROR(INDEX(Parámetros!$B$54:$B$60,MATCH($C17,Parámetros!$A$54:$A$60,0)),0)=1),ROUND($G17/(1+Parámetros!$B$13),0),$G17)) | J17: =IF($G17="","",IF(IFERROR(INDEX(Parámetros!$B$54:$B$60,MATCH($C17,Parámetros!$A$54:$A$60,0)),0)=1,ROUND($I17*Parámetros!$B$13,0),0)) | K17: =IF($G17="","",IF(IFERROR(INDEX(Parámetros!$C$54:$C$60,MATCH($C17,Parámetros!$A$54:$A$60,0)),0)=1,$J17,0)) | L17: =IF($G17="","",IF(IFERROR(INDEX(Parámetros!$D$54:$D$60,MATCH($C17,Parámetros!$A$54:$A$60,0)),0)=1,ROUND($I17*Parámetros!$B$16,0),0)) | M17: =IF($G17="","",$I17+$J17) | N17: =IF($G17="","",$M17-$L17) | S17: =IF($A17="","",YEAR($A17)) | T17: =IF($A17="","",MONTH($A17)) | U17: =IF($Q17="","",YEAR($Q17)) | V17: =IF($Q17="","",MONTH($Q17))
I18: =IF($G18="","",IF(AND($H18="Sí",IFERROR(INDEX(Parámetros!$B$54:$B$60,MATCH($C18,Parámetros!$A$54:$A$60,0)),0)=1),ROUND($G18/(1+Parámetros!$B$13),0),$G18)) | J18: =IF($G18="","",IF(IFERROR(INDEX(Parámetros!$B$54:$B$60,MATCH($C18,Parámetros!$A$54:$A$60,0)),0)=1,ROUND($I18*Parámetros!$B$13,0),0)) | K18: =IF($G18="","",IF(IFERROR(INDEX(Parámetros!$C$54:$C$60,MATCH($C18,Parámetros!$A$54:$A$60,0)),0)=1,$J18,0)) | L18: =IF($G18="","",IF(IFERROR(INDEX(Parámetros!$D$54:$D$60,MATCH($C18,Parámetros!$A$54:$A$60,0)),0)=1,ROUND($I18*Parámetros!$B$16,0),0)) | M18: =IF($G18="","",$I18+$J18) | N18: =IF($G18="","",$M18-$L18) | S18: =IF($A18="","",YEAR($A18)) | T18: =IF($A18="","",MONTH($A18)) | U18: =IF($Q18="","",YEAR($Q18)) | V18: =IF($Q18="","",MONTH($Q18))
I19: =IF($G19="","",IF(AND($H19="Sí",IFERROR(INDEX(Parámetros!$B$54:$B$60,MATCH($C19,Parámetros!$A$54:$A$60,0)),0)=1),ROUND($G19/(1+Parámetros!$B$13),0),$G19)) | J19: =IF($G19="","",IF(IFERROR(INDEX(Parámetros!$B$54:$B$60,MATCH($C19,Parámetros!$A$54:$A$60,0)),0)=1,ROUND($I19*Parámetros!$B$13,0),0)) | K19: =IF($G19="","",IF(IFERROR(INDEX(Parámetros!$C$54:$C$60,MATCH($C19,Parámetros!$A$54:$A$60,0)),0)=1,$J19,0)) | L19: =IF($G19="","",IF(IFERROR(INDEX(Parámetros!$D$54:$D$60,MATCH($C19,Parámetros!$A$54:$A$60,0)),0)=1,ROUND($I19*Parámetros!$B$16,0),0)) | M19: =IF($G19="","",$I19+$J19) | N19: =IF($G19="","",$M19-$L19) | S19: =IF($A19="","",YEAR($A19)) | T19: =IF($A19="","",MONTH($A19)) | U19: =IF($Q19="","",YEAR($Q19)) | V19: =IF($Q19="","",MONTH($Q19))
I20: =IF($G20="","",IF(AND($H20="Sí",IFERROR(INDEX(Parámetros!$B$54:$B$60,MATCH($C20,Parámetros!$A$54:$A$60,0)),0)=1),ROUND($G20/(1+Parámetros!$B$13),0),$G20)) | J20: =IF($G20="","",IF(IFERROR(INDEX(Parámetros!$B$54:$B$60,MATCH($C20,Parámetros!$A$54:$A$60,0)),0)=1,ROUND($I20*Parámetros!$B$13,0),0)) | K20: =IF($G20="","",IF(IFERROR(INDEX(Parámetros!$C$54:$C$60,MATCH($C20,Parámetros!$A$54:$A$60,0)),0)=1,$J20,0)) | L20: =IF($G20="","",IF(IFERROR(INDEX(Parámetros!$D$54:$D$60,MATCH($C20,Parámetros!$A$54:$A$60,0)),0)=1,ROUND($I20*Parámetros!$B$16,0),0)) | M20: =IF($G20="","",$I20+$J20) | N20: =IF($G20="","",$M20-$L20) | S20: =IF($A20="","",YEAR($A20)) | T20: =IF($A20="","",MONTH($A20)) | U20: =IF($Q20="","",YEAR($Q20)) | V20: =IF($Q20="","",MONTH($Q20))
I21: =IF($G21="","",IF(AND($H21="Sí",IFERROR(INDEX(Parámetros!$B$54:$B$60,MATCH($C21,Parámetros!$A$54:$A$60,0)),0)=1),ROUND($G21/(1+Parámetros!$B$13),0),$G21)) | J21: =IF($G21="","",IF(IFERROR(INDEX(Parámetros!$B$54:$B$60,MATCH($C21,Parámetros!$A$54:$A$60,0)),0)=1,ROUND($I21*Parámetros!$B$13,0),0)) | K21: =IF($G21="","",IF(IFERROR(INDEX(Parámetros!$C$54:$C$60,MATCH($C21,Parámetros!$A$54:$A$60,0)),0)=1,$J21,0)) | L21: =IF($G21="","",IF(IFERROR(INDEX(Parámetros!$D$54:$D$60,MATCH($C21,Parámetros!$A$54:$A$60,0)),0)=1,ROUND($I21*Parámetros!$B$16,0),0)) | M21: =IF($G21="","",$I21+$J21) | N21: =IF($G21="","",$M21-$L21) | S21: =IF($A21="","",YEAR($A21)) | T21: =IF($A21="","",MONTH($A21)) | U21: =IF($Q21="","",YEAR($Q21)) | V21: =IF($Q21="","",MONTH($Q21))
I22: =IF($G22="","",IF(AND($H22="Sí",IFERROR(INDEX(Parámetros!$B$54:$B$60,MATCH($C22,Parámetros!$A$54:$A$60,0)),0)=1),ROUND($G22/(1+Parámetros!$B$13),0),$G22)) | J22: =IF($G22="","",IF(IFERROR(INDEX(Parámetros!$B$54:$B$60,MATCH($C22,Parámetros!$A$54:$A$60,0)),0)=1,ROUND($I22*Parámetros!$B$13,0),0)) | K22: =IF($G22="","",IF(IFERROR(INDEX(Parámetros!$C$54:$C$60,MATCH($C22,Parámetros!$A$54:$A$60,0)),0)=1,$J22,0)) | L22: =IF($G22="","",IF(IFERROR(INDEX(Parámetros!$D$54:$D$60,MATCH($C22,Parámetros!$A$54:$A$60,0)),0)=1,ROUND($I22*Parámetros!$B$16,0),0)) | M22: =IF($G22="","",$I22+$J22) | N22: =IF($G22="","",$M22-$L22) | S22: =IF($A22="","",YEAR($A22)) | T22: =IF($A22="","",MONTH($A22)) | U22: =IF($Q22="","",YEAR($Q22)) | V22: =IF($Q22="","",MONTH($Q22))
... I257: =IF($G257="","",IF(AND($H257="Sí",IFERROR(INDEX(Parámetros!$B$54:$B$60,MATCH($C257,Parámetros!$A$54:$A$60,0)),0)=1),ROUND($G257/(1+Parámetros!$B$13),0),$G257)) | J257: =IF($G257="","",IF(IFERROR(INDEX(Parámetros!$B$54:$B$60,MATCH($C257,Parámetros!$A$54:$A$60,0)),0)=1,ROUND($I257*Parámetros!$B$13,0),0)) | K257: =IF($G257="","",IF(IFERROR(INDEX(Parámetros!$C$54:$C$60,MATCH($C257,Parámetros!$A$54:$A$60,0)),0)=1,$J257,0)) | L257: =IF($G257="","",IF(IFERROR(INDEX(Parámetros!$D$54:$D$60,MATCH($C257,Parámetros!$A$54:$A$60,0)),0)=1,ROUND($I257*Parámetros!$B$16,0),0)) | M257: =IF($G257="","",$I257+$J257) | N257: =IF($G257="","",$M257-$L257) | S257: =IF($A257="","",YEAR($A257)) | T257: =IF($A257="","",MONTH($A257)) | U257: =IF($Q257="","",YEAR($Q257)) | V257: =IF($Q257="","",MONTH($Q257))

Sheet Retiros
A1: Retiros hacia tu cuenta personal
A2: Cada giro de utilidades que te haces. No son gasto de la empresa: son utilidad que sacas, y pagan tu Global Complementario del año siguiente.
A4: Azul = lo escribes tú | D4: Negro = fórmula, no tocar | G4: Verde = viene de otra hoja
H6: Tu Impuesto Global Complementario (estimación)
A7: Fecha | B7: Monto ($) | C7: Cuenta destino | D7: Glosa / motivo | E7: Año | F7: Mes
A8: 46068 | B8: 800000 | C8: Banco personal · cta. corriente | D8: Retiro de utilidades febrero | E8: =IF($A8="","",YEAR($A8)) | F8: =IF($A8="","",MONTH($A8)) | H8: Retiros del año | I8: =SUMIFS($B$8:$B$67,$E$8:$E$67,Parámetros!$B$10)
E9: =IF($A9="","",YEAR($A9)) | F9: =IF($A9="","",MONTH($A9)) | H9: (+) Incremento por crédito de 1ª Categoría | I9: =ROUND(I8*(Parámetros!$B$14/(1-Parámetros!$B$14)),0)
E10: =IF($A10="","",YEAR($A10)) | F10: =IF($A10="","",MONTH($A10)) | H10: = Base bruta (renta a declarar) | I10: =I8+I9
E11: =IF($A11="","",YEAR($A11)) | F11: =IF($A11="","",MONTH($A11)) | H11: Valor UTA | I11: =Parámetros!$B$38
E12: =IF($A12="","",YEAR($A12)) | F12: =IF($A12="","",MONTH($A12)) | H12: Base en UTA | I12: =IFERROR(I10/I11,0)
E13: =IF($A13="","",YEAR($A13)) | F13: =IF($A13="","",MONTH($A13)) | H13: Tasa del tramo | I13: =IFERROR(INDEX(Parámetros!$C$42:$C$49,MATCH(I12,Parámetros!$A$42:$A$49,1)),0)
E14: =IF($A14="","",YEAR($A14)) | F14: =IF($A14="","",MONTH($A14)) | H14: Rebaja del tramo (UTA) | I14: =IFERROR(INDEX(Parámetros!$D$42:$D$49,MATCH(I12,Parámetros!$A$42:$A$49,1)),0)
E15: =IF($A15="","",YEAR($A15)) | F15: =IF($A15="","",MONTH($A15)) | H15: Impuesto según tabla | I15: =ROUND(MAX(0,I12*I13-I14)*I11,0)
E16: =IF($A16="","",YEAR($A16)) | F16: =IF($A16="","",MONTH($A16)) | H16: (−) Crédito por IDPC ya pagado | I16: =I9
E17: =IF($A17="","",YEAR($A17)) | F17: =IF($A17="","",MONTH($A17)) | H17: = Te toca pagar (o te devuelven) | I17: =I15-I16
E18: =IF($A18="","",YEAR($A18)) | F18: =IF($A18="","",MONTH($A18))
E19: =IF($A19="","",YEAR($A19)) | F19: =IF($A19="","",MONTH($A19)) | H19: ⚠ Es una estimación de ESTA fuente de renta solamente. Si además recibes sueldo, boletas de honorarios, arriendos o dividendos, todo se suma en la misma declaración y el tramo sube. Un resultado negativo significa devolución: el crédito de 1ª Categoría que ya pagó la empresa superó tu impuesto personal.
E20: =IF($A20="","",YEAR($A20)) | F20: =IF($A20="","",MONTH($A20))
E21: =IF($A21="","",YEAR($A21)) | F21: =IF($A21="","",MONTH($A21))
E22: =IF($A22="","",YEAR($A22)) | F22: =IF($A22="","",MONTH($A22))
E23: =IF($A23="","",YEAR($A23)) | F23: =IF($A23="","",MONTH($A23))
E24: =IF($A24="","",YEAR($A24)) | F24: =IF($A24="","",MONTH($A24))
E25: =IF($A25="","",YEAR($A25)) | F25: =IF($A25="","",MONTH($A25)) | H25: Cuánto puedes retirar sin descapitalizarte
E26: =IF($A26="","",YEAR($A26)) | F26: =IF($A26="","",MONTH($A26)) | H26: Utilidad del año después de impuesto | I26: =Renta!$C$18
E27: =IF($A27="","",YEAR($A27)) | F27: =IF($A27="","",MONTH($A27)) | H27: Retirado hasta ahora | I27: =I8
E28: =IF($A28="","",YEAR($A28)) | F28: =IF($A28="","",MONTH($A28)) | H28: = Margen que queda por retirar | I28: =I26-I27
E29: =IF($A29="","",YEAR($A29)) | F29: =IF($A29="","",MONTH($A29)) | H29: Caja disponible hoy | I29: =Flujo!$H$19
E30: =IF($A30="","",YEAR($A30)) | F30: =IF($A30="","",MONTH($A30))
E31: =IF($A31="","",YEAR($A31)) | F31: =IF($A31="","",MONTH($A31)) | H31: Retirar más que la utilidad no es ilegal, pero deja la empresa sin respaldo: revisa siempre las dos líneas. La de arriba te dice cuánto GANASTE; la de abajo, cuánta plata HAY.
E32: =IF($A32="","",YEAR($A32)) | F32: =IF($A32="","",MONTH($A32))
E33: =IF($A33="","",YEAR($A33)) | F33: =IF($A33="","",MONTH($A33))
E34: =IF($A34="","",YEAR($A34)) | F34: =IF($A34="","",MONTH($A34))
E35: =IF($A35="","",YEAR($A35)) | F35: =IF($A35="","",MONTH($A35))
E36: =IF($A36="","",YEAR($A36)) | F36: =IF($A36="","",MONTH($A36))
E37: =IF($A37="","",YEAR($A37)) | F37: =IF($A37="","",MONTH($A37))
E38: =IF($A38="","",YEAR($A38)) | F38: =IF($A38="","",MONTH($A38))
E39: =IF($A39="","",YEAR($A39)) | F39: =IF($A39="","",MONTH($A39))
E40: =IF($A40="","",YEAR($A40)) | F40: =IF($A40="","",MONTH($A40))
E41: =IF($A41="","",YEAR($A41)) | F41: =IF($A41="","",MONTH($A41))
E42: =IF($A42="","",YEAR($A42)) | F42: =IF($A42="","",MONTH($A42))
...

Sheet Mensual
A1: Mensual · IVA, PPM y retenciones
A2: Tu F29 mes a mes. Todo sale solo de Ingresos y Gastos: no se escribe nada acá.
A4: ⚠ Dos relojes distintos, a propósito: el IVA se declara según la fecha de EMISIÓN del documento (aunque no te hayan pagado), mientras que el PPM y las retenciones se calculan sobre lo efectivamente PERCIBIDO y PAGADO en el mes. Así funciona el régimen Pro Pyme y es el error más común de las planillas caseras.
A5: Cada fila se declara y paga hasta el día 12 del mes siguiente (día 20 si declaras y pagas por internet sin cheque).
A7: Mes | B7: N° | C7: Ventas netas | D7: Débito fiscal | E7: Compras netas | F7: Crédito fiscal | G7: Remanente mes ant. | H7: IVA determinado | I7: IVA a pagar | J7: Remanente al mes sig. | K7: Ingresos percibidos | L7: PPM | M7: Retenciones (cód. 153) | N7: TOTAL F29 del mes | O7: Se paga en
A8: Enero | B8: 1 | C8: =SUMIFS(Ingresos!$F$8:$F$157,Ingresos!$L$8:$L$157,Parámetros!$B$10,Ingresos!$M$8:$M$157,$B8) | D8: =SUMIFS(Ingresos!$G$8:$G$157,Ingresos!$L$8:$L$157,Parámetros!$B$10,Ingresos!$M$8:$M$157,$B8) | E8: =SUMIFS(Gastos!$I$8:$I$257,Gastos!$S$8:$S$257,Parámetros!$B$10,Gastos!$T$8:$T$257,$B8) | F8: =SUMIFS(Gastos!$K$8:$K$257,Gastos!$S$8:$S$257,Parámetros!$B$10,Gastos!$T$8:$T$257,$B8) | G8: =Parámetros!$B$22 | H8: =$D8-$F8-$G8 | I8: =MAX(0,$H8) | J8: =MAX(0,-$H8) | K8: =SUMIFS(Ingresos!$F$8:$F$157,Ingresos!$N$8:$N$157,Parámetros!$B$10,Ingresos!$O$8:$O$157,$B8) | L8: =ROUND($K8*Parámetros!$B$15,0) | M8: =SUMIFS(Gastos!$L$8:$L$257,Gastos!$U$8:$U$257,Parámetros!$B$10,Gastos!$V$8:$V$257,$B8) | N8: =$I8+$L8+$M8 | O8: Febrero
A9: Febrero | B9: 2 | C9: =SUMIFS(Ingresos!$F$8:$F$157,Ingresos!$L$8:$L$157,Parámetros!$B$10,Ingresos!$M$8:$M$157,$B9) | D9: =SUMIFS(Ingresos!$G$8:$G$157,Ingresos!$L$8:$L$157,Parámetros!$B$10,Ingresos!$M$8:$M$157,$B9) | E9: =SUMIFS(Gastos!$I$8:$I$257,Gastos!$S$8:$S$257,Parámetros!$B$10,Gastos!$T$8:$T$257,$B9) | F9: =SUMIFS(Gastos!$K$8:$K$257,Gastos!$S$8:$S$257,Parámetros!$B$10,Gastos!$T$8:$T$257,$B9) | G9: =$J8 | H9: =$D9-$F9-$G9 | I9: =MAX(0,$H9) | J9: =MAX(0,-$H9) | K9: =SUMIFS(Ingresos!$F$8:$F$157,Ingresos!$N$8:$N$157,Parámetros!$B$10,Ingresos!$O$8:$O$157,$B9) | L9: =ROUND($K9*Parámetros!$B$15,0) | M9: =SUMIFS(Gastos!$L$8:$L$257,Gastos!$U$8:$U$257,Parámetros!$B$10,Gastos!$V$8:$V$257,$B9) | N9: =$I9+$L9+$M9 | O9: Marzo
A10: Marzo | B10: 3 | C10: =SUMIFS(Ingresos!$F$8:$F$157,Ingresos!$L$8:$L$157,Parámetros!$B$10,Ingresos!$M$8:$M$157,$B10) | D10: =SUMIFS(Ingresos!$G$8:$G$157,Ingresos!$L$8:$L$157,Parámetros!$B$10,Ingresos!$M$8:$M$157,$B10) | E10: =SUMIFS(Gastos!$I$8:$I$257,Gastos!$S$8:$S$257,Parámetros!$B$10,Gastos!$T$8:$T$257,$B10) | F10: =SUMIFS(Gastos!$K$8:$K$257,Gastos!$S$8:$S$257,Parámetros!$B$10,Gastos!$T$8:$T$257,$B10) | G10: =$J9 | H10: =$D10-$F10-$G10 | I10: =MAX(0,$H10) | J10: =MAX(0,-$H10) | K10: =SUMIFS(Ingresos!$F$8:$F$157,Ingresos!$N$8:$N$157,Parámetros!$B$10,Ingresos!$O$8:$O$157,$B10) | L10: =ROUND($K10*Parámetros!$B$15,0) | M10: =SUMIFS(Gastos!$L$8:$L$257,Gastos!$U$8:$U$257,Parámetros!$B$10,Gastos!$V$8:$V$257,$B10) | N10: =$I10+$L10+$M10 | O10: Abril
A11: Abril | B11: 4 | C11: =SUMIFS(Ingresos!$F$8:$F$157,Ingresos!$L$8:$L$157,Parámetros!$B$10,Ingresos!$M$8:$M$157,$B11) | D11: =SUMIFS(Ingresos!$G$8:$G$157,Ingresos!$L$8:$L$157,Parámetros!$B$10,Ingresos!$M$8:$M$157,$B11) | E11: =SUMIFS(Gastos!$I$8:$I$257,Gastos!$S$8:$S$257,Parámetros!$B$10,Gastos!$T$8:$T$257,$B11) | F11: =SUMIFS(Gastos!$K$8:$K$257,Gastos!$S$8:$S$257,Parámetros!$B$10,Gastos!$T$8:$T$257,$B11) | G11: =$J10 | H11: =$D11-$F11-$G11 | I11: =MAX(0,$H11) | J11: =MAX(0,-$H11) | K11: =SUMIFS(Ingresos!$F$8:$F$157,Ingresos!$N$8:$N$157,Parámetros!$B$10,Ingresos!$O$8:$O$157,$B11) | L11: =ROUND($K11*Parámetros!$B$15,0) | M11: =SUMIFS(Gastos!$L$8:$L$257,Gastos!$U$8:$U$257,Parámetros!$B$10,Gastos!$V$8:$V$257,$B11) | N11: =$I11+$L11+$M11 | O11: Mayo
A12: Mayo | B12: 5 | C12: =SUMIFS(Ingresos!$F$8:$F$157,Ingresos!$L$8:$L$157,Parámetros!$B$10,Ingresos!$M$8:$M$157,$B12) | D12: =SUMIFS(Ingresos!$G$8:$G$157,Ingresos!$L$8:$L$157,Parámetros!$B$10,Ingresos!$M$8:$M$157,$B12) | E12: =SUMIFS(Gastos!$I$8:$I$257,Gastos!$S$8:$S$257,Parámetros!$B$10,Gastos!$T$8:$T$257,$B12) | F12: =SUMIFS(Gastos!$K$8:$K$257,Gastos!$S$8:$S$257,Parámetros!$B$10,Gastos!$T$8:$T$257,$B12) | G12: =$J11 | H12: =$D12-$F12-$G12 | I12: =MAX(0,$H12) | J12: =MAX(0,-$H12) | K12: =SUMIFS(Ingresos!$F$8:$F$157,Ingresos!$N$8:$N$157,Parámetros!$B$10,Ingresos!$O$8:$O$157,$B12) | L12: =ROUND($K12*Parámetros!$B$15,0) | M12: =SUMIFS(Gastos!$L$8:$L$257,Gastos!$U$8:$U$257,Parámetros!$B$10,Gastos!$V$8:$V$257,$B12) | N12: =$I12+$L12+$M12 | O12: Junio
A13: Junio | B13: 6 | C13: =SUMIFS(Ingresos!$F$8:$F$157,Ingresos!$L$8:$L$157,Parámetros!$B$10,Ingresos!$M$8:$M$157,$B13) | D13: =SUMIFS(Ingresos!$G$8:$G$157,Ingresos!$L$8:$L$157,Parámetros!$B$10,Ingresos!$M$8:$M$157,$B13) | E13: =SUMIFS(Gastos!$I$8:$I$257,Gastos!$S$8:$S$257,Parámetros!$B$10,Gastos!$T$8:$T$257,$B13) | F13: =SUMIFS(Gastos!$K$8:$K$257,Gastos!$S$8:$S$257,Parámetros!$B$10,Gastos!$T$8:$T$257,$B13) | G13: =$J12 | H13: =$D13-$F13-$G13 | I13: =MAX(0,$H13) | J13: =MAX(0,-$H13) | K13: =SUMIFS(Ingresos!$F$8:$F$157,Ingresos!$N$8:$N$157,Parámetros!$B$10,Ingresos!$O$8:$O$157,$B13) | L13: =ROUND($K13*Parámetros!$B$15,0) | M13: =SUMIFS(Gastos!$L$8:$L$257,Gastos!$U$8:$U$257,Parámetros!$B$10,Gastos!$V$8:$V$257,$B13) | N13: =$I13+$L13+$M13 | O13: Julio
A14: Julio | B14: 7 | C14: =SUMIFS(Ingresos!$F$8:$F$157,Ingresos!$L$8:$L$157,Parámetros!$B$10,Ingresos!$M$8:$M$157,$B14) | D14: =SUMIFS(Ingresos!$G$8:$G$157,Ingresos!$L$8:$L$157,Parámetros!$B$10,Ingresos!$M$8:$M$157,$B14) | E14: =SUMIFS(Gastos!$I$8:$I$257,Gastos!$S$8:$S$257,Parámetros!$B$10,Gastos!$T$8:$T$257,$B14) | F14: =SUMIFS(Gastos!$K$8:$K$257,Gastos!$S$8:$S$257,Parámetros!$B$10,Gastos!$T$8:$T$257,$B14) | G14: =$J13 | H14: =$D14-$F14-$G14 | I14: =MAX(0,$H14) | J14: =MAX(0,-$H14) | K14: =SUMIFS(Ingresos!$F$8:$F$157,Ingresos!$N$8:$N$157,Parámetros!$B$10,Ingresos!$O$8:$O$157,$B14) | L14: =ROUND($K14*Parámetros!$B$15,0) | M14: =SUMIFS(Gastos!$L$8:$L$257,Gastos!$U$8:$U$257,Parámetros!$B$10,Gastos!$V$8:$V$257,$B14) | N14: =$I14+$L14+$M14 | O14: Agosto
A15: Agosto | B15: 8 | C15: =SUMIFS(Ingresos!$F$8:$F$157,Ingresos!$L$8:$L$157,Parámetros!$B$10,Ingresos!$M$8:$M$157,$B15) | D15: =SUMIFS(Ingresos!$G$8:$G$157,Ingresos!$L$8:$L$157,Parámetros!$B$10,Ingresos!$M$8:$M$157,$B15) | E15: =SUMIFS(Gastos!$I$8:$I$257,Gastos!$S$8:$S$257,Parámetros!$B$10,Gastos!$T$8:$T$257,$B15) | F15: =SUMIFS(Gastos!$K$8:$K$257,Gastos!$S$8:$S$257,Parámetros!$B$10,Gastos!$T$8:$T$257,$B15) | G15: =$J14 | H15: =$D15-$F15-$G15 | I15: =MAX(0,$H15) | J15: =MAX(0,-$H15) | K15: =SUMIFS(Ingresos!$F$8:$F$157,Ingresos!$N$8:$N$157,Parámetros!$B$10,Ingresos!$O$8:$O$157,$B15) | L15: =ROUND($K15*Parámetros!$B$15,0) | M15: =SUMIFS(Gastos!$L$8:$L$257,Gastos!$U$8:$U$257,Parámetros!$B$10,Gastos!$V$8:$V$257,$B15) | N15: =$I15+$L15+$M15 | O15: Septiembre
A16: Septiembre | B16: 9 | C16: =SUMIFS(Ingresos!$F$8:$F$157,Ingresos!$L$8:$L$157,Parámetros!$B$10,Ingresos!$M$8:$M$157,$B16) | D16: =SUMIFS(Ingresos!$G$8:$G$157,Ingresos!$L$8:$L$157,Parámetros!$B$10,Ingresos!$M$8:$M$157,$B16) | E16: =SUMIFS(Gastos!$I$8:$I$257,Gastos!$S$8:$S$257,Parámetros!$B$10,Gastos!$T$8:$T$257,$B16) | F16: =SUMIFS(Gastos!$K$8:$K$257,Gastos!$S$8:$S$257,Parámetros!$B$10,Gastos!$T$8:$T$257,$B16) | G16: =$J15 | H16: =$D16-$F16-$G16 | I16: =MAX(0,$H16) | J16: =MAX(0,-$H16) | K16: =SUMIFS(Ingresos!$F$8:$F$157,Ingresos!$N$8:$N$157,Parámetros!$B$10,Ingresos!$O$8:$O$157,$B16) | L16: =ROUND($K16*Parámetros!$B$15,0) | M16: =SUMIFS(Gastos!$L$8:$L$257,Gastos!$U$8:$U$257,Parámetros!$B$10,Gastos!$V$8:$V$257,$B16) | N16: =$I16+$L16+$M16 | O16: Octubre
A17: Octubre | B17: 10 | C17: =SUMIFS(Ingresos!$F$8:$F$157,Ingresos!$L$8:$L$157,Parámetros!$B$10,Ingresos!$M$8:$M$157,$B17) | D17: =SUMIFS(Ingresos!$G$8:$G$157,Ingresos!$L$8:$L$157,Parámetros!$B$10,Ingresos!$M$8:$M$157,$B17) | E17: =SUMIFS(Gastos!$I$8:$I$257,Gastos!$S$8:$S$257,Parámetros!$B$10,Gastos!$T$8:$T$257,$B17) | F17: =SUMIFS(Gastos!$K$8:$K$257,Gastos!$S$8:$S$257,Parámetros!$B$10,Gastos!$T$8:$T$257,$B17) | G17: =$J16 | H17: =$D17-$F17-$G17 | I17: =MAX(0,$H17) | J17: =MAX(0,-$H17) | K17: =SUMIFS(Ingresos!$F$8:$F$157,Ingresos!$N$8:$N$157,Parámetros!$B$10,Ingresos!$O$8:$O$157,$B17) | L17: =ROUND($K17*Parámetros!$B$15,0) | M17: =SUMIFS(Gastos!$L$8:$L$257,Gastos!$U$8:$U$257,Parámetros!$B$10,Gastos!$V$8:$V$257,$B17) | N17: =$I17+$L17+$M17 | O17: Noviembre
A18: Noviembre | B18: 11 | C18: =SUMIFS(Ingresos!$F$8:$F$157,Ingresos!$L$8:$L$157,Parámetros!$B$10,Ingresos!$M$8:$M$157,$B18) | D18: =SUMIFS(Ingresos!$G$8:$G$157,Ingresos!$L$8:$L$157,Parámetros!$B$10,Ingresos!$M$8:$M$157,$B18) | E18: =SUMIFS(Gastos!$I$8:$I$257,Gastos!$S$8:$S$257,Parámetros!$B$10,Gastos!$T$8:$T$257,$B18) | F18: =SUMIFS(Gastos!$K$8:$K$257,Gastos!$S$8:$S$257,Parámetros!$B$10,Gastos!$T$8:$T$257,$B18) | G18: =$J17 | H18: =$D18-$F18-$G18 | I18: =MAX(0,$H18) | J18: =MAX(0,-$H18) | K18: =SUMIFS(Ingresos!$F$8:$F$157,Ingresos!$N$8:$N$157,Parámetros!$B$10,Ingresos!$O$8:$O$157,$B18) | L18: =ROUND($K18*Parámetros!$B$15,0) | M18: =SUMIFS(Gastos!$L$8:$L$257,Gastos!$U$8:$U$257,Parámetros!$B$10,Gastos!$V$8:$V$257,$B18) | N18: =$I18+$L18+$M18 | O18: Diciembre
A19: Diciembre | B19: 12 | C19: =SUMIFS(Ingresos!$F$8:$F$157,Ingresos!$L$8:$L$157,Parámetros!$B$10,Ingresos!$M$8:$M$157,$B19) | D19: =SUMIFS(Ingresos!$G$8:$G$157,Ingresos!$L$8:$L$157,Parámetros!$B$10,Ingresos!$M$8:$M$157,$B19) | E19: =SUMIFS(Gastos!$I$8:$I$257,Gastos!$S$8:$S$257,Parámetros!$B$10,Gastos!$T$8:$T$257,$B19) | F19: =SUMIFS(Gastos!$K$8:$K$257,Gastos!$S$8:$S$257,Parámetros!$B$10,Gastos!$T$8:$T$257,$B19) | G19: =$J18 | H19: =$D19-$F19-$G19 | I19: =MAX(0,$H19) | J19: =MAX(0,-$H19) | K19: =SUMIFS(Ingresos!$F$8:$F$157,Ingresos!$N$8:$N$157,Parámetros!$B$10,Ingresos!$O$8:$O$157,$B19) | L19: =ROUND($K19*Parámetros!$B$15,0) | M19: =SUMIFS(Gastos!$L$8:$L$257,Gastos!$U$8:$U$257,Parámetros!$B$10,Gastos!$V$8:$V$257,$B19) | N19: =$I19+$L19+$M19 | O19: Enero del año siguiente
A20: TOTAL AÑO | C20: =SUM(C8:C19) | D20: =SUM(D8:D19) | E20: =SUM(E8:E19) | F20: =SUM(F8:F19) | I20: =SUM(I8:I19) | J20: =J19 | K20: =SUM(K8:K19) | L20: =SUM(L8:L19) | M20: =SUM(M8:M19) | N20: =SUM(N8:N19)
A22: Remanente: cuando el crédito fiscal supera al débito, la diferencia no se pierde — se arrastra al mes siguiente. El SII lo reajusta por UTM; acá se arrastra nominal, diferencia menor para efectos de gestión.
A23: Retenciones código 153: es la plata que le descontaste al freelance de su boleta de honorarios. No es tuya, la enteras al SII en el F29 del mes en que le pagaste.

Sheet Renta
A1: Renta anual
A2: Lo que la empresa le debe al SII en abril del año siguiente. Régimen Pro Pyme General: base caja — ingresos percibidos menos gastos pagados.
A6: Determinación de la base imponible | E6: Gastos pagados por categoría
A7: Ingresos percibidos en el año | C7: =SUMIFS(Ingresos!$F$8:$F$157,Ingresos!$N$8:$N$157,Parámetros!$B$10) | E7: Categoría | F7: Monto ($) | G7: % del total | I7: Cobrados de verdad. Una factura emitida y no pagada NO tributa este año.
A8: (−) Gastos pagados y aceptados | C8: =-(SUMIFS(Gastos!$M$8:$M$257,Gastos!$U$8:$U$257,Parámetros!$B$10,Gastos!$O$8:$O$257,"Sí")-SUMIFS(Gastos!$K$8:$K$257,Gastos!$U$8:$U$257,Parámetros!$B$10,Gastos!$O$8:$O$257,"Sí")) | E8: =Parámetros!$A$72 | F8: =SUMIFS(Gastos!$M$8:$M$257,Gastos!$U$8:$U$257,Parámetros!$B$10,Gastos!$E$8:$E$257,$E8) | G8: =IFERROR($F8/$F$21,0) | I8: Total del documento menos el IVA que recuperaste: ese IVA no es gasto, se descuenta en el F29.
A9: = Base imponible | C9: =C7+C8 | E9: =Parámetros!$A$73 | F9: =SUMIFS(Gastos!$M$8:$M$257,Gastos!$U$8:$U$257,Parámetros!$B$10,Gastos!$E$8:$E$257,$E9) | G9: =IFERROR($F9/$F$21,0) | I9: Si sale negativa, es pérdida tributaria: no pagas 1ª Categoría y la arrastras al año siguiente.
E10: =Parámetros!$A$74 | F10: =SUMIFS(Gastos!$M$8:$M$257,Gastos!$U$8:$U$257,Parámetros!$B$10,Gastos!$E$8:$E$257,$E10) | G10: =IFERROR($F10/$F$21,0)
A11: Impuesto de la empresa | E11: =Parámetros!$A$75 | F11: =SUMIFS(Gastos!$M$8:$M$257,Gastos!$U$8:$U$257,Parámetros!$B$10,Gastos!$E$8:$E$257,$E11) | G11: =IFERROR($F11/$F$21,0)
A12: Impuesto de Primera Categoría | C12: =ROUND(MAX(0,C9)*Parámetros!$B$14,0) | E12: =Parámetros!$A$76 | F12: =SUMIFS(Gastos!$M$8:$M$257,Gastos!$U$8:$U$257,Parámetros!$B$10,Gastos!$E$8:$E$257,$E12) | G12: =IFERROR($F12/$F$21,0) | I12: Sólo sobre base positiva. La tasa vive en Parámetros §2.
A13: (−) PPM pagados durante el año | C13: =-Mensual!$L$20 | E13: =Parámetros!$A$77 | F13: =SUMIFS(Gastos!$M$8:$M$257,Gastos!$U$8:$U$257,Parámetros!$B$10,Gastos!$E$8:$E$257,$E13) | G13: =IFERROR($F13/$F$21,0) | I13: Los anticipos mensuales que ya enteraste. Vienen de la hoja Mensual.
A14: = Saldo a pagar en abril | C14: =C12+C13 | E14: =Parámetros!$A$78 | F14: =SUMIFS(Gastos!$M$8:$M$257,Gastos!$U$8:$U$257,Parámetros!$B$10,Gastos!$E$8:$E$257,$E14) | G14: =IFERROR($F14/$F$21,0) | I14: Negativo = el SII te devuelve. Positivo = lo pagas en la Operación Renta de abril.
E15: =Parámetros!$A$79 | F15: =SUMIFS(Gastos!$M$8:$M$257,Gastos!$U$8:$U$257,Parámetros!$B$10,Gastos!$E$8:$E$257,$E15) | G15: =IFERROR($F15/$F$21,0)
A16: Qué queda para ti | E16: =Parámetros!$A$80 | F16: =SUMIFS(Gastos!$M$8:$M$257,Gastos!$U$8:$U$257,Parámetros!$B$10,Gastos!$E$8:$E$257,$E16) | G16: =IFERROR($F16/$F$21,0)
A17: Base imponible | C17: =C9 | E17: =Parámetros!$A$81 | F17: =SUMIFS(Gastos!$M$8:$M$257,Gastos!$U$8:$U$257,Parámetros!$B$10,Gastos!$E$8:$E$257,$E17) | G17: =IFERROR($F17/$F$21,0)
A18: = Utilidad después de impuesto | C18: =C9-C12 | E18: =Parámetros!$A$82 | F18: =SUMIFS(Gastos!$M$8:$M$257,Gastos!$U$8:$U$257,Parámetros!$B$10,Gastos!$E$8:$E$257,$E18) | G18: =IFERROR($F18/$F$21,0) | I18: Este es el techo sano de lo que puedes retirar en el año.
A19: (−) Retiros ya hechos | C19: =-SUMIFS(Retiros!$B$8:$B$67,Retiros!$E$8:$E$67,Parámetros!$B$10) | E19: =Parámetros!$A$83 | F19: =SUMIFS(Gastos!$M$8:$M$257,Gastos!$U$8:$U$257,Parámetros!$B$10,Gastos!$E$8:$E$257,$E19) | G19: =IFERROR($F19/$F$21,0)
A20: = Utilidad que queda en la empresa | C20: =C18+C19 | E20: =Parámetros!$A$84 | F20: =SUMIFS(Gastos!$M$8:$M$257,Gastos!$U$8:$U$257,Parámetros!$B$10,Gastos!$E$8:$E$257,$E20) | G20: =IFERROR($F20/$F$21,0) | I20: Capital de trabajo. Si queda en cero y aún tienes gastos por pagar, retiraste de más.
E21: TOTAL | F21: =SUM(F8:F20) | G21: =IFERROR(F21/F21,0)
A23: ⚠ Esta hoja calcula el impuesto de la EMPRESA. El impuesto que pagas TÚ por los retiros se estima en la hoja Retiros. Son dos cosas distintas y las dos hay que pagarlas.
A24: Falta acá, a propósito, todo lo que exige contabilidad formal: corrección monetaria, depreciación del activo fijo y arrastre de pérdidas de años anteriores. Para una empresa de servicios sin activos pesados la diferencia es chica, pero el número oficial siempre lo firma tu contador.

Sheet Flujo
A1: Flujo de caja
A2: La plata de verdad, mes a mes. No mide si ganaste: mide si tienes con qué pagar.
A4: Se mueve con fechas de PAGO, no de emisión. Una factura enorme emitida en marzo y cobrada en junio aparece en junio.
A7: Mes | B7: N° | C7: Saldo inicial | D7: Cobros de clientes | E7: Pagos a proveedores | F7: Impuestos (F29) | G7: Retiros | H7: Saldo final
A8: Enero | B8: 1 | C8: =Parámetros!$B$21 | D8: =SUMIFS(Ingresos!$H$8:$H$157,Ingresos!$N$8:$N$157,Parámetros!$B$10,Ingresos!$O$8:$O$157,$B8) | E8: =-SUMIFS(Gastos!$N$8:$N$257,Gastos!$U$8:$U$257,Parámetros!$B$10,Gastos!$V$8:$V$257,$B8) | F8: =0 | G8: =-SUMIFS(Retiros!$B$8:$B$67,Retiros!$E$8:$E$67,Parámetros!$B$10,Retiros!$F$8:$F$67,$B8) | H8: =$C8+$D8+$E8+$F8+$G8 | J8: El F29 de enero se paga en febrero, así que la fila de enero no lleva impuesto y la de diciembre deja pendiente su propio F29 para enero del año siguiente.
A9: Febrero | B9: 2 | C9: =$H8 | D9: =SUMIFS(Ingresos!$H$8:$H$157,Ingresos!$N$8:$N$157,Parámetros!$B$10,Ingresos!$O$8:$O$157,$B9) | E9: =-SUMIFS(Gastos!$N$8:$N$257,Gastos!$U$8:$U$257,Parámetros!$B$10,Gastos!$V$8:$V$257,$B9) | F9: =-Mensual!$N8 | G9: =-SUMIFS(Retiros!$B$8:$B$67,Retiros!$E$8:$E$67,Parámetros!$B$10,Retiros!$F$8:$F$67,$B9) | H9: =$C9+$D9+$E9+$F9+$G9
A10: Marzo | B10: 3 | C10: =$H9 | D10: =SUMIFS(Ingresos!$H$8:$H$157,Ingresos!$N$8:$N$157,Parámetros!$B$10,Ingresos!$O$8:$O$157,$B10) | E10: =-SUMIFS(Gastos!$N$8:$N$257,Gastos!$U$8:$U$257,Parámetros!$B$10,Gastos!$V$8:$V$257,$B10) | F10: =-Mensual!$N9 | G10: =-SUMIFS(Retiros!$B$8:$B$67,Retiros!$E$8:$E$67,Parámetros!$B$10,Retiros!$F$8:$F$67,$B10) | H10: =$C10+$D10+$E10+$F10+$G10
A11: Abril | B11: 4 | C11: =$H10 | D11: =SUMIFS(Ingresos!$H$8:$H$157,Ingresos!$N$8:$N$157,Parámetros!$B$10,Ingresos!$O$8:$O$157,$B11) | E11: =-SUMIFS(Gastos!$N$8:$N$257,Gastos!$U$8:$U$257,Parámetros!$B$10,Gastos!$V$8:$V$257,$B11) | F11: =-Mensual!$N10 | G11: =-SUMIFS(Retiros!$B$8:$B$67,Retiros!$E$8:$E$67,Parámetros!$B$10,Retiros!$F$8:$F$67,$B11) | H11: =$C11+$D11+$E11+$F11+$G11
A12: Mayo | B12: 5 | C12: =$H11 | D12: =SUMIFS(Ingresos!$H$8:$H$157,Ingresos!$N$8:$N$157,Parámetros!$B$10,Ingresos!$O$8:$O$157,$B12) | E12: =-SUMIFS(Gastos!$N$8:$N$257,Gastos!$U$8:$U$257,Parámetros!$B$10,Gastos!$V$8:$V$257,$B12) | F12: =-Mensual!$N11 | G12: =-SUMIFS(Retiros!$B$8:$B$67,Retiros!$E$8:$E$67,Parámetros!$B$10,Retiros!$F$8:$F$67,$B12) | H12: =$C12+$D12+$E12+$F12+$G12
A13: Junio | B13: 6 | C13: =$H12 | D13: =SUMIFS(Ingresos!$H$8:$H$157,Ingresos!$N$8:$N$157,Parámetros!$B$10,Ingresos!$O$8:$O$157,$B13) | E13: =-SUMIFS(Gastos!$N$8:$N$257,Gastos!$U$8:$U$257,Parámetros!$B$10,Gastos!$V$8:$V$257,$B13) | F13: =-Mensual!$N12 | G13: =-SUMIFS(Retiros!$B$8:$B$67,Retiros!$E$8:$E$67,Parámetros!$B$10,Retiros!$F$8:$F$67,$B13) | H13: =$C13+$D13+$E13+$F13+$G13 | J13: Si un mes te queda en rojo, mira la columna de cobros: casi siempre el problema no es que gastes de más, sino que cobras tarde. Es el punto donde una empresa de servicios rentable igual se queda sin caja.
A14: Julio | B14: 7 | C14: =$H13 | D14: =SUMIFS(Ingresos!$H$8:$H$157,Ingresos!$N$8:$N$157,Parámetros!$B$10,Ingresos!$O$8:$O$157,$B14) | E14: =-SUMIFS(Gastos!$N$8:$N$257,Gastos!$U$8:$U$257,Parámetros!$B$10,Gastos!$V$8:$V$257,$B14) | F14: =-Mensual!$N13 | G14: =-SUMIFS(Retiros!$B$8:$B$67,Retiros!$E$8:$E$67,Parámetros!$B$10,Retiros!$F$8:$F$67,$B14) | H14: =$C14+$D14+$E14+$F14+$G14
A15: Agosto | B15: 8 | C15: =$H14 | D15: =SUMIFS(Ingresos!$H$8:$H$157,Ingresos!$N$8:$N$157,Parámetros!$B$10,Ingresos!$O$8:$O$157,$B15) | E15: =-SUMIFS(Gastos!$N$8:$N$257,Gastos!$U$8:$U$257,Parámetros!$B$10,Gastos!$V$8:$V$257,$B15) | F15: =-Mensual!$N14 | G15: =-SUMIFS(Retiros!$B$8:$B$67,Retiros!$E$8:$E$67,Parámetros!$B$10,Retiros!$F$8:$F$67,$B15) | H15: =$C15+$D15+$E15+$F15+$G15
A16: Septiembre | B16: 9 | C16: =$H15 | D16: =SUMIFS(Ingresos!$H$8:$H$157,Ingresos!$N$8:$N$157,Parámetros!$B$10,Ingresos!$O$8:$O$157,$B16) | E16: =-SUMIFS(Gastos!$N$8:$N$257,Gastos!$U$8:$U$257,Parámetros!$B$10,Gastos!$V$8:$V$257,$B16) | F16: =-Mensual!$N15 | G16: =-SUMIFS(Retiros!$B$8:$B$67,Retiros!$E$8:$E$67,Parámetros!$B$10,Retiros!$F$8:$F$67,$B16) | H16: =$C16+$D16+$E16+$F16+$G16
A17: Octubre | B17: 10 | C17: =$H16 | D17: =SUMIFS(Ingresos!$H$8:$H$157,Ingresos!$N$8:$N$157,Parámetros!$B$10,Ingresos!$O$8:$O$157,$B17) | E17: =-SUMIFS(Gastos!$N$8:$N$257,Gastos!$U$8:$U$257,Parámetros!$B$10,Gastos!$V$8:$V$257,$B17) | F17: =-Mensual!$N16 | G17: =-SUMIFS(Retiros!$B$8:$B$67,Retiros!$E$8:$E$67,Parámetros!$B$10,Retiros!$F$8:$F$67,$B17) | H17: =$C17+$D17+$E17+$F17+$G17
A18: Noviembre | B18: 11 | C18: =$H17 | D18: =SUMIFS(Ingresos!$H$8:$H$157,Ingresos!$N$8:$N$157,Parámetros!$B$10,Ingresos!$O$8:$O$157,$B18) | E18: =-SUMIFS(Gastos!$N$8:$N$257,Gastos!$U$8:$U$257,Parámetros!$B$10,Gastos!$V$8:$V$257,$B18) | F18: =-Mensual!$N17 | G18: =-SUMIFS(Retiros!$B$8:$B$67,Retiros!$E$8:$E$67,Parámetros!$B$10,Retiros!$F$8:$F$67,$B18) | H18: =$C18+$D18+$E18+$F18+$G18
A19: Diciembre | B19: 12 | C19: =$H18 | D19: =SUMIFS(Ingresos!$H$8:$H$157,Ingresos!$N$8:$N$157,Parámetros!$B$10,Ingresos!$O$8:$O$157,$B19) | E19: =-SUMIFS(Gastos!$N$8:$N$257,Gastos!$U$8:$U$257,Parámetros!$B$10,Gastos!$V$8:$V$257,$B19) | F19: =-Mensual!$N18 | G19: =-SUMIFS(Retiros!$B$8:$B$67,Retiros!$E$8:$E$67,Parámetros!$B$10,Retiros!$F$8:$F$67,$B19) | H19: =$C19+$D19+$E19+$F19+$G19
A20: TOTAL AÑO | D20: =SUM(D8:D19) | E20: =SUM(E8:E19) | F20: =SUM(F8:F19) | G20: =SUM(G8:G19)

Sheet Parámetros
A1: Parámetros
A2: Todo lo que el resto del libro usa para calcular vive acá. Cambia una celda azul y se recalcula el año completo.
A4: Azul = lo escribes tú | D4: Negro = fórmula, no tocar | G4: Verde = viene de otra hoja
A6: 1 · Identidad de la empresa
A7: Razón social | B7: GM Growth Partners SpA | F7: Ajústalo al nombre exacto de tu escritura.
A8: RUT | B8: 76.XXX.XXX-X | F8: Sólo para que los reportes salgan identificados.
A9: Giro | B9: Servicios de marketing y desarrollo digital
A10: Año de trabajo | B10: 2026 | F10: ⚠ Todas las hojas filtran por este año. Para llevar 2027, duplica el archivo y cambia esta celda.
A11: Régimen tributario | B11: Pro Pyme General | F11: Art. 14 letra D N°3 de la Ley de la Renta. Tributa sobre base CAJA: ingresos percibidos menos gastos pagados.
A12: 2 · Tasas tributarias vigentes
A13: IVA | B13: 0.19 | F13: Tasa general. No ha cambiado.
A14: Impuesto de Primera Categoría (IDPC) | B14: 0.125 | F14: Pro Pyme General, años comerciales 2025-2027 (rebaja transitoria Ley 21.755). Sube a 15% en 2028.
A15: Tasa de PPM mensual | B15: 0.00125 | F15: Pro Pyme General 2026: 0,25% rebajado a la mitad por la Ley 21.755. Si facturas más de 50.000 UF al año, la base es 0,5%.
A16: Retención de honorarios a terceros | B16: 0.1525 | F16: Desde el 1-ene-2026 (era 14,5% en 2025). Es lo que retienes al freelance que te da boleta de honorarios.
A18: ⚠ Verificado en agosto 2026 contra Circular SII N°53/2025 y Ley 21.755. Estas tasas son transitorias y cambian: confírmalas con tu contador cada enero y corrige la celda azul. Todo el libro se recalcula solo.
A20: 3 · Saldos con los que parte el año
A21: Caja + banco al 1 de enero | B21: 0 | F21: Suma de tus cuentas de la empresa el 31 de diciembre anterior. Es el punto de partida del flujo de caja.
A22: Remanente de crédito fiscal IVA arrastrado | B22: 0 | F22: Si en diciembre te sobró crédito fiscal, va acá. Lo verás en el código 77 de tu último F29.
A24: 4 · Valor de la UTM mes a mes
A25: Mes | B25: UTM ($)
A26: Enero | B26: 71649 | F26: Valor de referencia agosto 2026: $71.649. Actualízalo en sii.cl → Valores y fechas → UTM.
A27: Febrero | B27: 71649
A28: Marzo | B28: 71649
A29: Abril | B29: 71649
A30: Mayo | B30: 71649
A31: Junio | B31: 71649
A32: Julio | B32: 71649
A33: Agosto | B33: 71649
A34: Septiembre | B34: 71649
A35: Octubre | B35: 71649
A36: Noviembre | B36: 71649
A37: Diciembre | B37: 71649
A38: UTA (UTM de diciembre × 12) | B38: =B37*12 | F38: Unidad anual. La usa la estimación de tu Global Complementario en la hoja Retiros.
A40: 5 · Tramos del Impuesto Global Complementario (tabla anual del SII)
A41: Desde (UTA) | B41: Hasta (UTA) | C41: Tasa | D41: Rebaja (UTA) | E41: Desde ($) | F41: Rebaja ($)
A42: 0 | B42: 13.5 | C42: 0 | D42: 0 | E42: =A42*Parámetros!$B$38 | F42: =D42*Parámetros!$B$38
A43: 13.5 | B43: 30 | C43: 0.04 | D43: 0.54 | E43: =A43*Parámetros!$B$38 | F43: =D43*Parámetros!$B$38
A44: 30 | B44: 50 | C44: 0.08 | D44: 1.74 | E44: =A44*Parámetros!$B$38 | F44: =D44*Parámetros!$B$38
A45: 50 | B45: 70 | C45: 0.135 | D45: 4.49 | E45: =A45*Parámetros!$B$38 | F45: =D45*Parámetros!$B$38
A46: 70 | B46: 90 | C46: 0.23 | D46: 11.14 | E46: =A46*Parámetros!$B$38 | F46: =D46*Parámetros!$B$38
...
